<?xml version="1.0"?>
<robot name="humanoid_12dof">

  <!-- ========== TORSO (BASE LINK) ========== -->
  <link name="base_link">
    <visual>
      <geometry>
        <box size="0.3 0.2 0.4"/>
      </geometry>
      <material name="torso_blue">
        <color rgba="0.2 0.2 0.8 1.0"/>
      </material>
    </visual>
    <collision>
      <geometry>
        <box size="0.3 0.2 0.4"/>
      </geometry>
    </collision>
    <inertial>
      <mass value="15.0"/>
      <inertia ixx="0.45" ixy="0.0" ixz="0.0"
               iyy="0.55" iyz="0.0" izz="0.25"/>
    </inertial>
  </link>

  <!-- ========== HEAD ========== -->
  <link name="head">
    <visual>
      <geometry>
        <sphere radius="0.12"/>
      </geometry>
      <material name="head_gray">
        <color rgba="0.7 0.7 0.7 1.0"/>
      </material>
    </visual>
    <collision>
      <geometry>
        <sphere radius="0.12"/>
      </geometry>
    </collision>
    <inertial>
      <mass value="2.0"/>
      <inertia ixx="0.00576" ixy="0.0" ixz="0.0"
               iyy="0.00576" iyz="0.0" izz="0.00576"/>
    </inertial>
  </link>

  <joint name="neck_joint" type="revolute">
    <parent link="base_link"/>
    <child link="head"/>
    <origin xyz="0 0 0.25" rpy="0 0 0"/>
    <axis xyz="0 0 1"/>
    <limit lower="-0.785" upper="0.785" effort="10.0" velocity="2.0"/>
    <dynamics damping="0.5" friction="0.1"/>
  </joint>

  <!-- ========== LEFT LEG ========== -->

  <!-- Left Hip Link -->
  <link name="left_hip">
    <visual>
      <origin xyz="0 0 -0.15" rpy="0 0 0"/>
      <geometry>
        <cylinder length="0.3" radius="0.04"/>
      </geometry>
      <material name="leg_gray">
        <color rgba="0.5 0.5 0.5 1.0"/>
      </material>
    </visual>
    <collision>
      <origin xyz="0 0 -0.15" rpy="0 0 0"/>
      <geometry>
        <cylinder length="0.3" radius="0.04"/>
      </geometry>
    </collision>
    <inertial>
      <origin xyz="0 0 -0.15" rpy="0 0 0"/>
      <mass value="3.0"/>
      <inertia ixx="0.023" ixy="0.0" ixz="0.0"
               iyy="0.023" iyz="0.0" izz="0.0024"/>
    </inertial>
  </link>

  <joint name="left_hip_joint" type="revolute">
    <parent link="base_link"/>
    <child link="left_hip"/>
    <origin xyz="0 0.1 -0.2" rpy="0 0 0"/>
    <axis xyz="0 1 0"/>
    <limit lower="-1.57" upper="1.57" effort="150.0" velocity="3.0"/>
    <dynamics damping="1.0" friction="0.2"/>
  </joint>

  <!-- Left Knee Link -->
  <link name="left_knee">
    <visual>
      <origin xyz="0 0 -0.15" rpy="0 0 0"/>
      <geometry>
        <cylinder length="0.3" radius="0.035"/>
      </geometry>
      <material name="leg_gray"/>
    </visual>
    <collision>
      <origin xyz="0 0 -0.15" rpy="0 0 0"/>
      <geometry>
        <cylinder length="0.3" radius="0.035"/>
      </geometry>
    </collision>
    <inertial>
      <origin xyz="0 0 -0.15" rpy="0 0 0"/>
      <mass value="2.0"/>
      <inertia ixx="0.015" ixy="0.0" ixz="0.0"
               iyy="0.015" iyz="0.0" izz="0.0012"/>
    </inertial>
  </link>

  <joint name="left_knee_joint" type="revolute">
    <parent link="left_hip"/>
    <child link="left_knee"/>
    <origin xyz="0 0 -0.3" rpy="0 0 0"/>
    <axis xyz="0 1 0"/>
    <limit lower="0.0" upper="2.356" effort="150.0" velocity="3.0"/>
    <dynamics damping="1.0" friction="0.2"/>
  </joint>

  <!-- Left Ankle Link -->
  <link name="left_ankle">
    <visual>
      <origin xyz="0.05 0 -0.025" rpy="0 0 0"/>
      <geometry>
        <box size="0.15 0.08 0.05"/>
      </geometry>
      <material name="foot_black">
        <color rgba="0.1 0.1 0.1 1.0"/>
      </material>
    </visual>
    <collision>
      <origin xyz="0.05 0 -0.025" rpy="0 0 0"/>
      <geometry>
        <box size="0.15 0.08 0.05"/>
      </geometry>
    </collision>
    <inertial>
      <origin xyz="0.05 0 -0.025" rpy="0 0 0"/>
      <mass value="1.0"/>
      <inertia ixx="0.00067" ixy="0.0" ixz="0.0"
               iyy="0.00208" iyz="0.0" izz="0.00242"/>
    </inertial>
  </link>

  <joint name="left_ankle_joint" type="revolute">
    <parent link="left_knee"/>
    <child link="left_ankle"/>
    <origin xyz="0 0 -0.3" rpy="0 0 0"/>
    <axis xyz="0 1 0"/>
    <limit lower="-0.785" upper="0.785" effort="100.0" velocity="2.0"/>
    <dynamics damping="0.5" friction="0.1"/>
  </joint>

  <!-- ========== RIGHT LEG (SYMMETRIC) ========== -->

  <link name="right_hip">
    <visual>
      <origin xyz="0 0 -0.15" rpy="0 0 0"/>
      <geometry>
        <cylinder length="0.3" radius="0.04"/>
      </geometry>
      <material name="leg_gray"/>
    </visual>
    <collision>
      <origin xyz="0 0 -0.15" rpy="0 0 0"/>
      <geometry>
        <cylinder length="0.3" radius="0.04"/>
      </geometry>
    </collision>
    <inertial>
      <origin xyz="0 0 -0.15" rpy="0 0 0"/>
      <mass value="3.0"/>
      <inertia ixx="0.023" ixy="0.0" ixz="0.0"
               iyy="0.023" iyz="0.0" izz="0.0024"/>
    </inertial>
  </link>

  <joint name="right_hip_joint" type="revolute">
    <parent link="base_link"/>
    <child link="right_hip"/>
    <origin xyz="0 -0.1 -0.2" rpy="0 0 0"/>
    <axis xyz="0 1 0"/>
    <limit lower="-1.57" upper="1.57" effort="150.0" velocity="3.0"/>
    <dynamics damping="1.0" friction="0.2"/>
  </joint>

  <link name="right_knee">
    <visual>
      <origin xyz="0 0 -0.15" rpy="0 0 0"/>
      <geometry>
        <cylinder length="0.3" radius="0.035"/>
      </geometry>
      <material name="leg_gray"/>
    </visual>
    <collision>
      <origin xyz="0 0 -0.15" rpy="0 0 0"/>
      <geometry>
        <cylinder length="0.3" radius="0.035"/>
      </geometry>
    </collision>
    <inertial>
      <origin xyz="0 0 -0.15" rpy="0 0 0"/>
      <mass value="2.0"/>
      <inertia ixx="0.015" ixy="0.0" ixz="0.0"
               iyy="0.015" iyz="0.0" izz="0.0012"/>
    </inertial>
  </link>

  <joint name="right_knee_joint" type="revolute">
    <parent link="right_hip"/>
    <child link="right_knee"/>
    <origin xyz="0 0 -0.3" rpy="0 0 0"/>
    <axis xyz="0 1 0"/>
    <limit lower="0.0" upper="2.356" effort="150.0" velocity="3.0"/>
    <dynamics damping="1.0" friction="0.2"/>
  </joint>

  <link name="right_ankle">
    <visual>
      <origin xyz="0.05 0 -0.025" rpy="0 0 0"/>
      <geometry>
        <box size="0.15 0.08 0.05"/>
      </geometry>
      <material name="foot_black"/>
    </visual>
    <collision>
      <origin xyz="0.05 0 -0.025" rpy="0 0 0"/>
      <geometry>
        <box size="0.15 0.08 0.05"/>
      </geometry>
    </collision>
    <inertial>
      <origin xyz="0.05 0 -0.025" rpy="0 0 0"/>
      <mass value="1.0"/>
      <inertia ixx="0.00067" ixy="0.0" ixz="0.0"
               iyy="0.00208" iyz="0.0" izz="0.00242"/>
    </inertial>
  </link>

  <joint name="right_ankle_joint" type="revolute">
    <parent link="right_knee"/>
    <child link="right_ankle"/>
    <origin xyz="0 0 -0.3" rpy="0 0 0"/>
    <axis xyz="0 1 0"/>
    <limit lower="-0.785" upper="0.785" effort="100.0" velocity="2.0"/>
    <dynamics damping="0.5" friction="0.1"/>
  </joint>

  <!-- ========== LEFT ARM ========== -->

  <link name="left_shoulder">
    <visual>
      <origin xyz="0 0 -0.12" rpy="0 0 0"/>
      <geometry>
        <cylinder length="0.24" radius="0.03"/>
      </geometry>
      <material name="arm_gray">
        <color rgba="0.6 0.6 0.6 1.0"/>
      </material>
    </visual>
    <collision>
      <origin xyz="0 0 -0.12" rpy="0 0 0"/>
      <geometry>
        <cylinder length="0.24" radius="0.03"/>
      </geometry>
    </collision>
    <inertial>
      <origin xyz="0 0 -0.12" rpy="0 0 0"/>
      <mass value="1.5"/>
      <inertia ixx="0.0072" ixy="0.0" ixz="0.0"
               iyy="0.0072" iyz="0.0" izz="0.00068"/>
    </inertial>
  </link>

  <joint name="left_shoulder_joint" type="revolute">
    <parent link="base_link"/>
    <child link="left_shoulder"/>
    <origin xyz="0 0.15 0.15" rpy="0 0 0"/>
    <axis xyz="0 1 0"/>
    <limit lower="-1.57" upper="1.57" effort="80.0" velocity="2.5"/>
    <dynamics damping="0.5" friction="0.1"/>
  </joint>

  <link name="left_elbow">
    <visual>
      <origin xyz="0 0 -0.1" rpy="0 0 0"/>
      <geometry>
        <cylinder length="0.2" radius="0.025"/>
      </geometry>
      <material name="arm_gray"/>
    </visual>
    <collision>
      <origin xyz="0 0 -0.1" rpy="0 0 0"/>
      <geometry>
        <cylinder length="0.2" radius="0.025"/>
      </geometry>
    </collision>
    <inertial>
      <origin xyz="0 0 -0.1" rpy="0 0 0"/>
      <mass value="1.0"/>
      <inertia ixx="0.0033" ixy="0.0" ixz="0.0"
               iyy="0.0033" iyz="0.0" izz="0.00031"/>
    </inertial>
  </link>

  <joint name="left_elbow_joint" type="revolute">
    <parent link="left_shoulder"/>
    <child link="left_elbow"/>
    <origin xyz="0 0 -0.24" rpy="0 0 0"/>
    <axis xyz="0 1 0"/>
    <limit lower="0.0" upper="2.356" effort="60.0" velocity="2.5"/>
    <dynamics damping="0.3" friction="0.05"/>
  </joint>

  <!-- ========== RIGHT ARM (SYMMETRIC) ========== -->

  <link name="right_shoulder">
    <visual>
      <origin xyz="0 0 -0.12" rpy="0 0 0"/>
      <geometry>
        <cylinder length="0.24" radius="0.03"/>
      </geometry>
      <material name="arm_gray"/>
    </visual>
    <collision>
      <origin xyz="0 0 -0.12" rpy="0 0 0"/>
      <geometry>
        <cylinder length="0.24" radius="0.03"/>
      </geometry>
    </collision>
    <inertial>
      <origin xyz="0 0 -0.12" rpy="0 0 0"/>
      <mass value="1.5"/>
      <inertia ixx="0.0072" ixy="0.0" ixz="0.0"
               iyy="0.0072" iyz="0.0" izz="0.00068"/>
    </inertial>
  </link>

  <joint name="right_shoulder_joint" type="revolute">
    <parent link="base_link"/>
    <child link="right_shoulder"/>
    <origin xyz="0 -0.15 0.15" rpy="0 0 0"/>
    <axis xyz="0 1 0"/>
    <limit lower="-1.57" upper="1.57" effort="80.0" velocity="2.5"/>
    <dynamics damping="0.5" friction="0.1"/>
  </joint>

  <link name="right_elbow">
    <visual>
      <origin xyz="0 0 -0.1" rpy="0 0 0"/>
      <geometry>
        <cylinder length="0.2" radius="0.025"/>
      </geometry>
      <material name="arm_gray"/>
    </visual>
    <collision>
      <origin xyz="0 0 -0.1" rpy="0 0 0"/>
      <geometry>
        <cylinder length="0.2" radius="0.025"/>
      </geometry>
    </collision>
    <inertial>
      <origin xyz="0 0 -0.1" rpy="0 0 0"/>
      <mass value="1.0"/>
      <inertia ixx="0.0033" ixy="0.0" ixz="0.0"
               iyy="0.0033" iyz="0.0" izz="0.00031"/>
    </inertial>
  </link>

  <joint name="right_elbow_joint" type="revolute">
    <parent link="right_shoulder"/>
    <child link="right_elbow"/>
    <origin xyz="0 0 -0.24" rpy="0 0 0"/>
    <axis xyz="0 1 0"/>
    <limit lower="0.0" upper="2.356" effort="60.0" velocity="2.5"/>
    <dynamics damping="0.3" friction="0.05"/>
  </joint>

</robot>
